<sdf version='1.11'>
  <model name='go2_description'>
    <link name='base_link'>
      <inertial>
        <pose>0.021189390726563631 0 -0.0053716721074678611 0 0 0</pose>
        <mass>6.923</mass>
        <inertia>
          <ixx>0.02450242076517968</ixx>
          <ixy>0.00012166</ixy>
          <ixz>0.0014956963870049491</ixz>
          <iyy>0.098242939262173756</iyy>
          <iyz>-3.1199999999999999e-05</iyz>
          <izz>0.1071627184969941</izz>
        </inertia>
      </inertial>
      <collision name='base_link_collision'>
        <pose>0 0 0 0 0 0</pose>
        <geometry>
          <box>
            <size>0.37619999999999998 0.0935 0.114</size>
          </box>
        </geometry>
      </collision>
      <collision name='base_link_fixed_joint_lump__Head_upper_collision_1'>
        <pose>0.28499999999999998 0 0.01 0 0 0</pose>
        <geometry>
          <cylinder>
            <length>0.089999999999999997</length>
            <radius>0.050000000000000003</radius>
          </cylinder>
        </geometry>
      </collision>
      <collision name='base_link_fixed_joint_lump__Head_lower_collision_2'>
        <pose>0.29299999999999998 0 -0.059999999999999998 0 0 0</pose>
        <geometry>
          <sphere>
            <radius>0.047</radius>
          </sphere>
        </geometry>
      </collision>
      <collision name='base_link_fixed_joint_lump__utlidar_lidar_collision_3'>
        <pose>0.28944999999999999 0 -0.046824999999999999 0 0 0</pose>
        <geometry>
          <cylinder>
            <length>0.040000000000000001</length>
            <radius>0.025000000000000001</radius>
          </cylinder>
        </geometry>
        <surface>
          <contact>
            <ode/>
          </contact>
          <friction>
            <ode/>
          </friction>
        </surface>
      </collision>
      <visual name='base_link_visual'>
        <pose>0 0 0 0 0 0</pose>
        <geometry>
          <mesh>
            <scale>1 1 1</scale>
            <uri>model://go2_description/dae/base.dae</uri>
          </mesh>
        </geometry>
        <material>
          <diffuse>1 1 1 1</diffuse>
          <ambient>1 1 1 1</ambient>
        </material>
      </visual>
      <visual name='base_link_fixed_joint_lump__utlidar_lidar_visual_1'>
        <pose>0.28944999999999999 0 -0.046824999999999999 0 0 0</pose>
        <geometry>
          <cylinder>
            <length>0.040000000000000001</length>
            <radius>0.025000000000000001</radius>
          </cylinder>
        </geometry>
        <material>
          <diffuse>0 0 0 1</diffuse>
          <ambient>0 0 0 1</ambient>
        </material>
      </visual>
      <sensor name='imu_sensor' type='imu'>
        <always_on>true</always_on>
        <update_rate>200</update_rate>
        <visualize>true</visualize>
        <topic>imu</topic>
        <imu>
          <angular_velocity>
            <x>
              <noise type='gaussian'>
                <mean>0</mean>
                <stddev>0.01</stddev>
              </noise>
            </x>
            <y>
              <noise type='gaussian'>
                <mean>0</mean>
                <stddev>0.01</stddev>
              </noise>
            </y>
            <z>
              <noise type='gaussian'>
                <mean>0</mean>
                <stddev>0.01</stddev>
              </noise>
            </z>
          </angular_velocity>
          <linear_acceleration>
            <x>
              <noise type='gaussian'>
                <mean>0</mean>
                <stddev>0.1</stddev>
              </noise>
            </x>
            <y>
              <noise type='gaussian'>
                <mean>0</mean>
                <stddev>0.1</stddev>
              </noise>
            </y>
            <z>
              <noise type='gaussian'>
                <mean>0</mean>
                <stddev>0.1</stddev>
              </noise>
            </z>
          </linear_acceleration>
        </imu>
      </sensor>

      <!-- 2D 激光雷达（GZ Sim 用 gpu_lidar 配单线） -->
      <sensor name='lidar_sensor' type='gpu_lidar'>
        <always_on>true</always_on>
        <visualize>true</visualize>
        <update_rate>10</update_rate>
        <topic>scan</topic>
        <lidar>
          <scan>
            <horizontal>
              <samples>360</samples>
              <resolution>1</resolution>
              <min_angle>-3.14159</min_angle>
              <max_angle>3.14159</max_angle>
            </horizontal>
            <vertical>
              <samples>1</samples>  <!-- 单线，2D -->
              <resolution>1</resolution>
              <min_angle>0</min_angle>
              <max_angle>0</max_angle>
            </vertical>
          </scan>
          <range>
            <min>0.1</min>
            <max>30.0</max>
            <resolution>0.01</resolution>
          </range>
        </lidar>
      </sensor>
    </link>
    <joint name='FL_hip_joint' type='revolute'>
      <pose relative_to='base_link'>0.19339999999999999 0.0465 0 0 0 0</pose>
      <parent>base_link</parent>
      <child>FL_hip</child>
      <axis>
        <xyz>1 0 0</xyz>
        <limit>
          <lower>-1.0471999999999999</lower>
          <upper>1.0471999999999999</upper>
          <effort>23.699999999999999</effort>
          <velocity>30.100000000000001</velocity>
        </limit>
        <dynamics>
          <spring_reference>0</spring_reference>
          <spring_stiffness>0</spring_stiffness>
        </dynamics>
      </axis>
      <physics>
        <ode>
          <limit>
            <cfm>0</cfm>
            <erp>0.20000000000000001</erp>
          </limit>
        </ode>
      </physics>
      <dynamics damping='0.1' friction='0.1'/>
    </joint>
    <link name='FL_hip'>
      <pose relative_to='FL_hip_joint'>0 0 0 0 0 0</pose>
      <inertial>
        <pose>-0.0054000000000000003 0.0019400000000000001 -0.000105 0 0 0</pose>
        <mass>0.67800000000000005</mass>
        <inertia>
          <ixx>0.00048000000000000001</ixx>
          <ixy>-3.01e-06</ixy>
          <ixz>1.11e-06</ixz>
          <iyy>0.00088400000000000002</iyy>
          <iyz>-1.42e-06</iyz>
          <izz>0.00059599999999999996</izz>
        </inertia>
      </inertial>
      <collision name='FL_hip_collision'>
        <pose>0 0.080000000000000002 0 1.5707963267948959 0 0</pose>
        <geometry>
          <cylinder>
            <length>0.040000000000000001</length>
            <radius>0.045999999999999999</radius>
          </cylinder>
        </geometry>
      </collision>
      <visual name='FL_hip_visual'>
        <pose>0 0 0 0 0 0</pose>
        <geometry>
          <mesh>
            <scale>1 1 1</scale>
            <uri>model://go2_description/dae/hip.dae</uri>
          </mesh>
        </geometry>
        <material>
          <diffuse>1 1 1 1</diffuse>
          <ambient>1 1 1 1</ambient>
        </material>
      </visual>
    </link>
    <joint name='FL_thigh_joint' type='revolute'>
      <pose relative_to='FL_hip'>0 0.095500000000000002 0 0 0 0</pose>
      <parent>FL_hip</parent>
      <child>FL_thigh</child>
      <axis>
        <xyz>0 1 0</xyz>
        <limit>
          <lower>-1.5708</lower>
          <upper>3.4906999999999999</upper>
          <effort>23.699999999999999</effort>
          <velocity>30.100000000000001</velocity>
        </limit>
        <dynamics>
          <spring_reference>0</spring_reference>
          <spring_stiffness>0</spring_stiffness>
        </dynamics>
      </axis>
      <physics>
        <ode>
          <limit>
            <cfm>0</cfm>
            <erp>0.20000000000000001</erp>
          </limit>
        </ode>
      </physics>
      <dynamics damping='0.1' friction='0.1'/>
    </joint>
    <link name='FL_thigh'>
      <pose relative_to='FL_thigh_joint'>0 0 0 0 0 0</pose>
      <inertial>
        <pose>-0.0037399999999999998 -0.0223 -0.0327 0 0 0</pose>
        <mass>1.1519999999999999</mass>
        <inertia>
          <ixx>0.0058399999999999997</ixx>
          <ixy>8.7200000000000005e-05</ixy>
          <ixz>-0.00028899999999999998</ixz>
          <iyy>0.0057999999999999996</iyy>
          <iyz>0.00080800000000000002</iyz>
          <izz>0.0010300000000000001</izz>
        </inertia>
      </inertial>
      <collision name='FL_thigh_collision'>
        <pose>0 0 -0.1065 0 1.5707963267948966 0</pose>
        <geometry>
          <box>
            <size>0.21299999999999999 0.024500000000000001 0.034000000000000002</size>
          </box>
        </geometry>
      </collision>
      <visual name='FL_thigh_visual'>
        <pose>0 0 0 0 0 0</pose>
        <geometry>
          <mesh>
            <scale>1 1 1</scale>
            <uri>model://go2_description/dae/thigh.dae</uri>
          </mesh>
        </geometry>
        <material>
          <diffuse>1 1 1 1</diffuse>
          <ambient>1 1 1 1</ambient>
        </material>
      </visual>
    </link>
    <joint name='FL_calf_joint' type='revolute'>
      <pose relative_to='FL_thigh'>0 0 -0.21299999999999999 0 0 0</pose>
      <parent>FL_thigh</parent>
      <child>FL_calf</child>
      <axis>
        <xyz>0 1 0</xyz>
        <limit>
          <lower>-2.7227000000000001</lower>
          <upper>-0.83775999999999995</upper>
          <effort>45.43</effort>
          <velocity>15.699999999999999</velocity>
        </limit>
        <dynamics>
          <spring_reference>0</spring_reference>
          <spring_stiffness>0</spring_stiffness>
        </dynamics>
      </axis>
      <physics>
        <ode>
          <limit>
            <cfm>0</cfm>
            <erp>0.20000000000000001</erp>
          </limit>
        </ode>
      </physics>
      <dynamics damping='0.1' friction='0.1'/>
    </joint>
    <link name='FL_calf'>
      <pose relative_to='FL_calf_joint'>0 0 0 0 0 0</pose>
      <inertial>
        <pose>0.0043501030927835041 -0.00077396907216494828 -0.13520618556701031 0 0 0</pose>
        <mass>0.19400000000000001</mass>
        <inertia>
          <ixx>0.001394581937371134</ixx>
          <ixy>5.0965402061855686e-07</ixy>
          <ixz>1.4759587628868399e-07</ixz>
          <iyy>0.001415505295175258</iyy>
          <iyz>1.1313958762886591e-05</iyz>
          <izz>4.3483727391752568e-05</izz>
        </inertia>
      </inertial>
      <collision name='FL_calf_collision'>
        <pose>0.0080000000000000002 0 -0.059999999999999998 0 -0.20999999999999999 0</pose>
        <geometry>
          <cylinder>
            <length>0.12</length>
            <radius>0.012</radius>
          </cylinder>
        </geometry>
      </collision>
      <collision name='FL_calf_fixed_joint_lump__FL_foot_collision_1'>
        <pose>-0.002 0 -0.21299999999999999 0 0 0</pose>
        <geometry>
          <sphere>
            <radius>0.021999999999999999</radius>
          </sphere>
        </geometry>
      </collision>
      <visual name='FL_calf_visual'>
        <pose>0 0 0 0 0 0</pose>
        <geometry>
          <mesh>
            <scale>1 1 1</scale>
            <uri>model://go2_description/dae/calf.dae</uri>
          </mesh>
        </geometry>
        <material>
          <diffuse>1 1 1 1</diffuse>
          <ambient>1 1 1 1</ambient>
        </material>
      </visual>
      <visual name='FL_calf_fixed_joint_lump__FL_foot_visual_1'>
        <pose>0 0 -0.21299999999999999 0 0 0</pose>
        <geometry>
          <mesh>
            <scale>1 1 1</scale>
            <uri>model://go2_description/dae/foot.dae</uri>
          </mesh>
        </geometry>
        <material>
          <diffuse>1 1 1 1</diffuse>
          <ambient>1 1 1 1</ambient>
        </material>
      </visual>
    </link>
    <joint name='FR_hip_joint' type='revolute'>
      <pose relative_to='base_link'>0.19339999999999999 -0.0465 0 0 0 0</pose>
      <parent>base_link</parent>
      <child>FR_hip</child>
      <axis>
        <xyz>1 0 0</xyz>
        <limit>
          <lower>-1.0471999999999999</lower>
          <upper>1.0471999999999999</upper>
          <effort>23.699999999999999</effort>
          <velocity>30.100000000000001</velocity>
        </limit>
        <dynamics>
          <spring_reference>0</spring_reference>
          <spring_stiffness>0</spring_stiffness>
        </dynamics>
      </axis>
      <physics>
        <ode>
          <limit>
            <cfm>0</cfm>
            <erp>0.20000000000000001</erp>
          </limit>
        </ode>
      </physics>
      <dynamics damping='0.1' friction='0.1'/>
    </joint>
    <link name='FR_hip'>
      <pose relative_to='FR_hip_joint'>0 0 0 0 0 0</pose>
      <inertial>
        <pose>-0.0054000000000000003 -0.0019400000000000001 -0.000105 0 0 0</pose>
        <mass>0.67800000000000005</mass>
        <inertia>
          <ixx>0.00048000000000000001</ixx>
          <ixy>3.01e-06</ixy>
          <ixz>1.11e-06</ixz>
          <iyy>0.00088400000000000002</iyy>
          <iyz>1.42e-06</iyz>
          <izz>0.00059599999999999996</izz>
        </inertia>
      </inertial>
      <collision name='FR_hip_collision'>
        <pose>0 -0.080000000000000002 0 1.5707963267948959 0 0</pose>
        <geometry>
          <cylinder>
            <length>0.040000000000000001</length>
            <radius>0.045999999999999999</radius>
          </cylinder>
        </geometry>
      </collision>
      <visual name='FR_hip_visual'>
        <pose>0 0 0 3.1415000000000002 0 0</pose>
        <geometry>
          <mesh>
            <scale>1 1 1</scale>
            <uri>model://go2_description/dae/hip.dae</uri>
          </mesh>
        </geometry>
        <material>
          <diffuse>1 1 1 1</diffuse>
          <ambient>1 1 1 1</ambient>
        </material>
      </visual>
    </link>
    <joint name='FR_thigh_joint' type='revolute'>
      <pose relative_to='FR_hip'>0 -0.095500000000000002 0 0 0 0</pose>
      <parent>FR_hip</parent>
      <child>FR_thigh</child>
      <axis>
        <xyz>0 1 0</xyz>
        <limit>
          <lower>-1.5708</lower>
          <upper>3.4906999999999999</upper>
          <effort>23.699999999999999</effort>
          <velocity>30.100000000000001</velocity>
        </limit>
        <dynamics>
          <spring_reference>0</spring_reference>
          <spring_stiffness>0</spring_stiffness>
        </dynamics>
      </axis>
      <physics>
        <ode>
          <limit>
            <cfm>0</cfm>
            <erp>0.20000000000000001</erp>
          </limit>
        </ode>
      </physics>
      <dynamics damping='0.1' friction='0.1'/>
    </joint>
    <link name='FR_thigh'>
      <pose relative_to='FR_thigh_joint'>0 0 0 0 0 0</pose>
      <inertial>
        <pose>-0.0037399999999999998 0.0223 -0.0327 0 0 0</pose>
        <mass>1.1519999999999999</mass>
        <inertia>
          <ixx>0.0058399999999999997</ixx>
          <ixy>-8.7200000000000005e-05</ixy>
          <ixz>-0.00028899999999999998</ixz>
          <iyy>0.0057999999999999996</iyy>
          <iyz>-0.00080800000000000002</iyz>
          <izz>0.0010300000000000001</izz>
        </inertia>
      </inertial>
      <collision name='FR_thigh_collision'>
        <pose>0 0 -0.1065 0 1.5707963267948966 0</pose>
        <geometry>
          <box>
            <size>0.21299999999999999 0.024500000000000001 0.034000000000000002</size>
          </box>
        </geometry>
      </collision>
      <visual name='FR_thigh_visual'>
        <pose>0 0 0 0 0 0</pose>
        <geometry>
          <mesh>
            <scale>1 1 1</scale>
            <uri>model://go2_description/dae/thigh_mirror.dae</uri>
          </mesh>
        </geometry>
        <material>
          <diffuse>1 1 1 1</diffuse>
          <ambient>1 1 1 1</ambient>
        </material>
      </visual>
    </link>
    <joint name='FR_calf_joint' type='revolute'>
      <pose relative_to='FR_thigh'>0 0 -0.21299999999999999 0 0 0</pose>
      <parent>FR_thigh</parent>
      <child>FR_calf</child>
      <axis>
        <xyz>0 1 0</xyz>
        <limit>
          <lower>-2.7227000000000001</lower>
          <upper>-0.83775999999999995</upper>
          <effort>45.43</effort>
          <velocity>15.699999999999999</velocity>
        </limit>
        <dynamics>
          <spring_reference>0</spring_reference>
          <spring_stiffness>0</spring_stiffness>
        </dynamics>
      </axis>
      <physics>
        <ode>
          <limit>
            <cfm>0</cfm>
            <erp>0.20000000000000001</erp>
          </limit>
        </ode>
      </physics>
      <dynamics damping='0.1' friction='0.1'/>
    </joint>
    <link name='FR_calf'>
      <pose relative_to='FR_calf_joint'>0 0 0 0 0 0</pose>
      <inertial>
        <pose>0.0043501030927835041 0.00077396907216494828 -0.13520618556701031 0 0 0</pose>
        <mass>0.19400000000000001</mass>
        <inertia>
          <ixx>0.001394581937371134</ixx>
          <ixy>-5.0965402061855686e-07</ixy>
          <ixz>1.4759587628868399e-07</ixz>
          <iyy>0.001415505295175258</iyy>
          <iyz>-1.1313958762886591e-05</iyz>
          <izz>4.3483727391752568e-05</izz>
        </inertia>
      </inertial>
      <collision name='FR_calf_collision'>
        <pose>0.01 0 -0.059999999999999998 0 -0.20000000000000004 0</pose>
        <geometry>
          <cylinder>
            <length>0.12</length>
            <radius>0.012999999999999999</radius>
          </cylinder>
        </geometry>
      </collision>
      <collision name='FR_calf_fixed_joint_lump__FR_foot_collision_1'>
        <pose>-0.002 0 -0.21299999999999999 0 0 0</pose>
        <geometry>
          <sphere>
            <radius>0.021999999999999999</radius>
          </sphere>
        </geometry>
      </collision>
      <visual name='FR_calf_visual'>
        <pose>0 0 0 0 0 0</pose>
        <geometry>
          <mesh>
            <scale>1 1 1</scale>
            <uri>model://go2_description/dae/calf_mirror.dae</uri>
          </mesh>
        </geometry>
        <material>
          <diffuse>1 1 1 1</diffuse>
          <ambient>1 1 1 1</ambient>
        </material>
      </visual>
      <visual name='FR_calf_fixed_joint_lump__FR_foot_visual_1'>
        <pose>0 0 -0.21299999999999999 0 0 0</pose>
        <geometry>
          <mesh>
            <scale>1 1 1</scale>
            <uri>model://go2_description/dae/foot.dae</uri>
          </mesh>
        </geometry>
        <material>
          <diffuse>1 1 1 1</diffuse>
          <ambient>1 1 1 1</ambient>
        </material>
      </visual>
    </link>
    <joint name='RL_hip_joint' type='revolute'>
      <pose relative_to='base_link'>-0.19339999999999999 0.0465 0 0 0 0</pose>
      <parent>base_link</parent>
      <child>RL_hip</child>
      <axis>
        <xyz>1 0 0</xyz>
        <limit>
          <lower>-1.0471999999999999</lower>
          <upper>1.0471999999999999</upper>
          <effort>23.699999999999999</effort>
          <velocity>30.100000000000001</velocity>
        </limit>
        <dynamics>
          <spring_reference>0</spring_reference>
          <spring_stiffness>0</spring_stiffness>
        </dynamics>
      </axis>
      <physics>
        <ode>
          <limit>
            <cfm>0</cfm>
            <erp>0.20000000000000001</erp>
          </limit>
        </ode>
      </physics>
      <dynamics damping='0.1' friction='0.1'/>
    </joint>
    <link name='RL_hip'>
      <pose relative_to='RL_hip_joint'>0 0 0 0 0 0</pose>
      <inertial>
        <pose>0.0054000000000000003 0.0019400000000000001 -0.000105 0 0 0</pose>
        <mass>0.67800000000000005</mass>
        <inertia>
          <ixx>0.00048000000000000001</ixx>
          <ixy>3.01e-06</ixy>
          <ixz>-1.11e-06</ixz>
          <iyy>0.00088400000000000002</iyy>
          <iyz>-1.42e-06</iyz>
          <izz>0.00059599999999999996</izz>
        </inertia>
      </inertial>
      <collision name='RL_hip_collision'>
        <pose>0 0.080000000000000002 0 1.5707963267948959 0 0</pose>
        <geometry>
          <cylinder>
            <length>0.040000000000000001</length>
            <radius>0.045999999999999999</radius>
          </cylinder>
        </geometry>
      </collision>
      <visual name='RL_hip_visual'>
        <pose>0 0 0 3.1415926535897931 9.265358979305727e-05 3.1415926535897931</pose>
        <geometry>
          <mesh>
            <scale>1 1 1</scale>
            <uri>model://go2_description/dae/hip.dae</uri>
          </mesh>
        </geometry>
        <material>
          <diffuse>1 1 1 1</diffuse>
          <ambient>1 1 1 1</ambient>
        </material>
      </visual>
    </link>
    <joint name='RL_thigh_joint' type='revolute'>
      <pose relative_to='RL_hip'>0 0.095500000000000002 0 0 0 0</pose>
      <parent>RL_hip</parent>
      <child>RL_thigh</child>
      <axis>
        <xyz>0 1 0</xyz>
        <limit>
          <lower>-0.52359999999999995</lower>
          <upper>4.5378999999999996</upper>
          <effort>23.699999999999999</effort>
          <velocity>30.100000000000001</velocity>
        </limit>
        <dynamics>
          <spring_reference>0</spring_reference>
          <spring_stiffness>0</spring_stiffness>
        </dynamics>
      </axis>
      <physics>
        <ode>
          <limit>
            <cfm>0</cfm>
            <erp>0.20000000000000001</erp>
          </limit>
        </ode>
      </physics>
      <dynamics damping='0.1' friction='0.1'/>
    </joint>
    <link name='RL_thigh'>
      <pose relative_to='RL_thigh_joint'>0 0 0 0 0 0</pose>
      <inertial>
        <pose>-0.0037399999999999998 -0.0223 -0.0327 0 0 0</pose>
        <mass>1.1519999999999999</mass>
        <inertia>
          <ixx>0.0058399999999999997</ixx>
          <ixy>8.7200000000000005e-05</ixy>
          <ixz>-0.00028899999999999998</ixz>
          <iyy>0.0057999999999999996</iyy>
          <iyz>0.00080800000000000002</iyz>
          <izz>0.0010300000000000001</izz>
        </inertia>
      </inertial>
      <collision name='RL_thigh_collision'>
        <pose>0 0 -0.1065 0 1.5707963267948966 0</pose>
        <geometry>
          <box>
            <size>0.21299999999999999 0.024500000000000001 0.034000000000000002</size>
          </box>
        </geometry>
      </collision>
      <visual name='RL_thigh_visual'>
        <pose>0 0 0 0 0 0</pose>
        <geometry>
          <mesh>
            <scale>1 1 1</scale>
            <uri>model://go2_description/dae/thigh.dae</uri>
          </mesh>
        </geometry>
        <material>
          <diffuse>1 1 1 1</diffuse>
          <ambient>1 1 1 1</ambient>
        </material>
      </visual>
    </link>
    <joint name='RL_calf_joint' type='revolute'>
      <pose relative_to='RL_thigh'>0 0 -0.21299999999999999 0 0 0</pose>
      <parent>RL_thigh</parent>
      <child>RL_calf</child>
      <axis>
        <xyz>0 1 0</xyz>
        <limit>
          <lower>-2.7227000000000001</lower>
          <upper>-0.83775999999999995</upper>
          <effort>45.43</effort>
          <velocity>15.699999999999999</velocity>
        </limit>
        <dynamics>
          <spring_reference>0</spring_reference>
          <spring_stiffness>0</spring_stiffness>
        </dynamics>
      </axis>
      <physics>
        <ode>
          <limit>
            <cfm>0</cfm>
            <erp>0.20000000000000001</erp>
          </limit>
        </ode>
      </physics>
      <dynamics damping='0.1' friction='0.1'/>
    </joint>
    <link name='RL_calf'>
      <pose relative_to='RL_calf_joint'>0 0 0 0 0 0</pose>
      <inertial>
        <pose>0.0043501030927835041 -0.00077396907216494828 -0.13520618556701031 0 0 0</pose>
        <mass>0.19400000000000001</mass>
        <inertia>
          <ixx>0.001394581937371134</ixx>
          <ixy>5.0965402061855686e-07</ixy>
          <ixz>1.4759587628868399e-07</ixz>
          <iyy>0.001415505295175258</iyy>
          <iyz>1.1313958762886591e-05</iyz>
          <izz>4.3483727391752568e-05</izz>
        </inertia>
      </inertial>
      <collision name='RL_calf_collision'>
        <pose>0.01 0 -0.059999999999999998 0 -0.20000000000000004 0</pose>
        <geometry>
          <cylinder>
            <length>0.12</length>
            <radius>0.012999999999999999</radius>
          </cylinder>
        </geometry>
      </collision>
      <collision name='RL_calf_fixed_joint_lump__RL_foot_collision_1'>
        <pose>-0.002 0 -0.21299999999999999 0 0 0</pose>
        <geometry>
          <sphere>
            <radius>0.021999999999999999</radius>
          </sphere>
        </geometry>
      </collision>
      <visual name='RL_calf_visual'>
        <pose>0 0 0 0 0 0</pose>
        <geometry>
          <mesh>
            <scale>1 1 1</scale>
            <uri>model://go2_description/dae/calf.dae</uri>
          </mesh>
        </geometry>
        <material>
          <diffuse>1 1 1 1</diffuse>
          <ambient>1 1 1 1</ambient>
        </material>
      </visual>
      <visual name='RL_calf_fixed_joint_lump__RL_foot_visual_1'>
        <pose>0 0 -0.21299999999999999 0 0 0</pose>
        <geometry>
          <mesh>
            <scale>1 1 1</scale>
            <uri>model://go2_description/dae/foot.dae</uri>
          </mesh>
        </geometry>
        <material>
          <diffuse>1 1 1 1</diffuse>
          <ambient>1 1 1 1</ambient>
        </material>
      </visual>
    </link>
    <joint name='RR_hip_joint' type='revolute'>
      <pose relative_to='base_link'>-0.19339999999999999 -0.0465 0 0 0 0</pose>
      <parent>base_link</parent>
      <child>RR_hip</child>
      <axis>
        <xyz>1 0 0</xyz>
        <limit>
          <lower>-1.0471999999999999</lower>
          <upper>1.0471999999999999</upper>
          <effort>23.699999999999999</effort>
          <velocity>30.100000000000001</velocity>
        </limit>
        <dynamics>
          <spring_reference>0</spring_reference>
          <spring_stiffness>0</spring_stiffness>
        </dynamics>
      </axis>
      <physics>
        <ode>
          <limit>
            <cfm>0</cfm>
            <erp>0.20000000000000001</erp>
          </limit>
        </ode>
      </physics>
      <dynamics damping='0.1' friction='0.1'/>
    </joint>
    <link name='RR_hip'>
      <pose relative_to='RR_hip_joint'>0 0 0 0 0 0</pose>
      <inertial>
        <pose>0.0054000000000000003 -0.0019400000000000001 -0.000105 0 0 0</pose>
        <mass>0.67800000000000005</mass>
        <inertia>
          <ixx>0.00048000000000000001</ixx>
          <ixy>-3.01e-06</ixy>
          <ixz>-1.11e-06</ixz>
          <iyy>0.00088400000000000002</iyy>
          <iyz>1.42e-06</iyz>
          <izz>0.00059599999999999996</izz>
        </inertia>
      </inertial>
      <collision name='RR_hip_collision'>
        <pose>0 -0.080000000000000002 0 1.5707963267948959 0 0</pose>
        <geometry>
          <cylinder>
            <length>0.040000000000000001</length>
            <radius>0.045999999999999999</radius>
          </cylinder>
        </geometry>
      </collision>
      <visual name='RR_hip_visual'>
        <pose>0 0 0 -9.2653589793057257e-05 9.2653589793057284e-05 3.1415926535897931</pose>
        <geometry>
          <mesh>
            <scale>1 1 1</scale>
            <uri>model://go2_description/dae/hip.dae</uri>
          </mesh>
        </geometry>
        <material>
          <diffuse>1 1 1 1</diffuse>
          <ambient>1 1 1 1</ambient>
        </material>
      </visual>
    </link>
    <joint name='RR_thigh_joint' type='revolute'>
      <pose relative_to='RR_hip'>0 -0.095500000000000002 0 0 0 0</pose>
      <parent>RR_hip</parent>
      <child>RR_thigh</child>
      <axis>
        <xyz>0 1 0</xyz>
        <limit>
          <lower>-0.52359999999999995</lower>
          <upper>4.5378999999999996</upper>
          <effort>23.699999999999999</effort>
          <velocity>30.100000000000001</velocity>
        </limit>
        <dynamics>
          <spring_reference>0</spring_reference>
          <spring_stiffness>0</spring_stiffness>
        </dynamics>
      </axis>
      <physics>
        <ode>
          <limit>
            <cfm>0</cfm>
            <erp>0.20000000000000001</erp>
          </limit>
        </ode>
      </physics>
      <dynamics damping='0.1' friction='0.1'/>
    </joint>
    <link name='RR_thigh'>
      <pose relative_to='RR_thigh_joint'>0 0 0 0 0 0</pose>
      <inertial>
        <pose>-0.0037399999999999998 0.0223 -0.0327 0 0 0</pose>
        <mass>1.1519999999999999</mass>
        <inertia>
          <ixx>0.0058399999999999997</ixx>
          <ixy>-8.7200000000000005e-05</ixy>
          <ixz>-0.00028899999999999998</ixz>
          <iyy>0.0057999999999999996</iyy>
          <iyz>-0.00080800000000000002</iyz>
          <izz>0.0010300000000000001</izz>
        </inertia>
      </inertial>
      <collision name='RR_thigh_collision'>
        <pose>0 0 -0.1065 0 1.5707963267948966 0</pose>
        <geometry>
          <box>
            <size>0.21299999999999999 0.024500000000000001 0.034000000000000002</size>
          </box>
        </geometry>
      </collision>
      <visual name='RR_thigh_visual'>
        <pose>0 0 0 0 0 0</pose>
        <geometry>
          <mesh>
            <scale>1 1 1</scale>
            <uri>model://go2_description/dae/thigh_mirror.dae</uri>
          </mesh>
        </geometry>
        <material>
          <diffuse>1 1 1 1</diffuse>
          <ambient>1 1 1 1</ambient>
        </material>
      </visual>
    </link>
    <joint name='RR_calf_joint' type='revolute'>
      <pose relative_to='RR_thigh'>0 0 -0.21299999999999999 0 0 0</pose>
      <parent>RR_thigh</parent>
      <child>RR_calf</child>
      <axis>
        <xyz>0 1 0</xyz>
        <limit>
          <lower>-2.7227000000000001</lower>
          <upper>-0.83775999999999995</upper>
          <effort>45.43</effort>
          <velocity>15.699999999999999</velocity>
        </limit>
        <dynamics>
          <spring_reference>0</spring_reference>
          <spring_stiffness>0</spring_stiffness>
        </dynamics>
      </axis>
      <physics>
        <ode>
          <limit>
            <cfm>0</cfm>
            <erp>0.20000000000000001</erp>
          </limit>
        </ode>
      </physics>
      <dynamics damping='0.1' friction='0.1'/>
    </joint>
    <link name='RR_calf'>
      <pose relative_to='RR_calf_joint'>0 0 0 0 0 0</pose>
      <inertial>
        <pose>0.0043501030927835041 0.00077396907216494828 -0.13520618556701031 0 0 0</pose>
        <mass>0.19400000000000001</mass>
        <inertia>
          <ixx>0.001394581937371134</ixx>
          <ixy>-5.0965402061855686e-07</ixy>
          <ixz>1.4759587628868399e-07</ixz>
          <iyy>0.001415505295175258</iyy>
          <iyz>-1.1313958762886591e-05</iyz>
          <izz>4.3483727391752568e-05</izz>
        </inertia>
      </inertial>
      <collision name='RR_calf_collision'>
        <pose>0.01 0 -0.059999999999999998 0 -0.20000000000000004 0</pose>
        <geometry>
          <cylinder>
            <length>0.12</length>
            <radius>0.012999999999999999</radius>
          </cylinder>
        </geometry>
      </collision>
      <collision name='RR_calf_fixed_joint_lump__RR_foot_collision_1'>
        <pose>-0.002 0 -0.21299999999999999 0 0 0</pose>
        <geometry>
          <sphere>
            <radius>0.021999999999999999</radius>
          </sphere>
        </geometry>
      </collision>
      <visual name='RR_calf_visual'>
        <pose>0 0 0 0 0 0</pose>
        <geometry>
          <mesh>
            <scale>1 1 1</scale>
            <uri>model://go2_description/dae/calf_mirror.dae</uri>
          </mesh>
        </geometry>
        <material>
          <diffuse>1 1 1 1</diffuse>
          <ambient>1 1 1 1</ambient>
        </material>
      </visual>
      <visual name='RR_calf_fixed_joint_lump__RR_foot_visual_1'>
        <pose>0 0 -0.21299999999999999 0 0 0</pose>
        <geometry>
          <mesh>
            <scale>1 1 1</scale>
            <uri>model://go2_description/dae/foot.dae</uri>
          </mesh>
        </geometry>
        <material>
          <diffuse>1 1 1 1</diffuse>
          <ambient>1 1 1 1</ambient>
        </material>
      </visual>
    </link>
    <frame name='Head_lower_joint' attached_to='Head_upper'>
      <pose>0.0080000000000000002 0 -0.070000000000000007 0 0 0</pose>
    </frame>
    <frame name='Head_lower' attached_to='Head_lower_joint'>
      <pose>0 0 0 0 0 0</pose>
    </frame>
    <frame name='Head_upper_joint' attached_to='base_link'>
      <pose>0.28499999999999998 0 0.01 0 0 0</pose>
    </frame>
    <frame name='Head_upper' attached_to='Head_upper_joint'>
      <pose>0 0 0 0 0 0</pose>
    </frame>
    <frame name='imu_joint' attached_to='base_link'>
      <pose>-0.025569999999999999 0 0.042320000000000003 0 0 0</pose>
    </frame>
    <frame name='imu' attached_to='imu_joint'>
      <pose>0 0 0 0 0 0</pose>
    </frame>
    <frame name='utlidar_lidar_joint' attached_to='base_link'>
      <pose>0.28944999999999999 0 -0.046824999999999999 0 0 0</pose>
    </frame>
    <frame name='utlidar_lidar' attached_to='utlidar_lidar_joint'>
      <pose>0 0 0 0 0 0</pose>
    </frame>
    <frame name='FL_foot_joint' attached_to='FL_calf'>
      <pose>0 0 -0.21299999999999999 0 0 0</pose>
    </frame>
    <frame name='FL_foot' attached_to='FL_foot_joint'>
      <pose>0 0 0 0 0 0</pose>
    </frame>
    <frame name='FR_foot_joint' attached_to='FR_calf'>
      <pose>0 0 -0.21299999999999999 0 0 0</pose>
    </frame>
    <frame name='FR_foot' attached_to='FR_foot_joint'>
      <pose>0 0 0 0 0 0</pose>
    </frame>
    <frame name='RL_foot_joint' attached_to='RL_calf'>
      <pose>0 0 -0.21299999999999999 0 0 0</pose>
    </frame>
    <frame name='RL_foot' attached_to='RL_foot_joint'>
      <pose>0 0 0 0 0 0</pose>
    </frame>
    <frame name='RR_foot_joint' attached_to='RR_calf'>
      <pose>0 0 -0.21299999999999999 0 0 0</pose>
    </frame>
    <frame name='RR_foot' attached_to='RR_foot_joint'>
      <pose>0 0 0 0 0 0</pose>
    </frame>
  </model>
</sdf>
